<?xml version="1.0" ?>
<!-- =================================================================================== -->
<!-- |    This document was autogenerated by xacro from hyq.urdf.xacro                 | -->
<!-- |    EDITING THIS FILE BY HAND IS NOT RECOMMENDED                                 | -->
<!-- =================================================================================== -->
<robot name="hyq" xmlns:xacro="http://ros.org/wiki/xacro">
  <!-- The following included files set up definitions of parts of the robot body -->
  <!-- standard distances -->
  <!-- Inertial values -->
  <!-- Trunk with hydraulic system -->
  <!-- Hip assembly -->
  <!-- Upper leg -->
  <!-- Lower leg -->
  <!-- PTU unit -->
  <!-- Asus Xtion Camera Location (Nominally 0) -->
  <!-- Kinect Camera Location (Nominally 0) -->
  <!-- Bumblebee mass and lengths for computing inertia tensor -->
  <!-- Velodyne Lidar Location (Nominally 0) -->
  <!-- HighDef Camera Location (Nominally 0) -->
  <!-- HyQ trunk -->
  <!-- Things that are needed only for Gazebo (not the physical robot). These include sensor and controller plugin specifications -->
  <!-- ================================ Trunk ================================ -->
  <!-- The xacro macro xacro:hyq_base contains: base and trunk -->
  <!-- HyQ legs -->
  <!-- Things that are needed only for Gazebo (not the physical robot). These include sensor and controller plugin specifications -->
  <!-- ================================== Leg ================================== -->
  <!-- The xacro macro xacro:hyq_leg contains: hip assembly, upper and lower leg -->
  <!-- HyQ sensors -->
  <!-- ============================ IMU microstrain ============================== -->
  <!-- The xacro macro xacro:microstrain_3dmgx325_imu: imu frame -->
  <!-- ===================================== ASUS & PROSILICA ==================================== -->
  <!-- The xacro macro xacro:asus_xtion_camera contains: asus xtion and prosilica combo -->
  <!-- ===================================== VELODYNE ==================================== -->
  <!-- The xacro macro xacro:velodyne contains: velodyne combo -->
  <!-- FIXME: what is this offset? -->
  <!-- ===================================== KINECT & PROSILICA ==================================== -->
  <!-- The xacro macro xacro:kinect_prosilica_camera_swept_back contains: kinect and prosilica combo -->
  <!-- Things that are needed only for Gazebo (not the physical robot). These include sensor and controller plugin specifications -->
  <!-- ================================ Bumblebee ============================== -->
  <!-- The xacro macro xacro:bumblebee contains: camera, mount and optical frame -->
  <!-- A bumblebee with a 97-degre HFOV lens -->
  <!-- A bumblebee with a 66-degre HFOV lens -->
  <!-- A bumblebee with a 43-degre HFOV lens -->
  <!-- A vislab 3dve with a 72-degre HFOV lens -->
  <!-- generic simulator_gazebo plugins for starting mechanism control, ros time -->
  <gazebo>
    <plugin filename="libgazebo_ros_control.so" name="gazebo_ros_controller_manager">
      <robotNamespace>/hyq</robotNamespace>
      <controlPeriod>0.005</controlPeriod>
    </plugin>
    <plugin filename="libgazebo_ros_p3d.so" name="gazebo_ros_p3d">
      <robotNamespace>/hyq</robotNamespace>
      <bodyName>base_link</bodyName>
      <topicName>ground_truth_odom</topicName>
      <frameName>world</frameName>
      <xyzOffsets>0 0 0</xyzOffsets>
      <rpyOffsets>0 0 0</rpyOffsets>
      <gaussianNoise>0</gaussianNoise>
      <alwaysOn>true</alwaysOn>
      <updateRate>200.0</updateRate>
    </plugin>
  </gazebo>
  <!-- Now we can start using the macros included above to define the actual HyQ -->
  <!-- The first use of a macro. This one was defined in trunk.urdf.xacro above.
A macro like this will expand to a set of link and joint definitions, and to additional
Gazebo-related extensions (sensor plugins, etc). The macro takes an argument, name,
that equals "base", and uses it to generate names for its component links and joints
(e.g., base_link). The included origin block is also an argument to the macro. By convention,
the origin block defines where the component is w.r.t its parent (in this case the parent
is the world frame). For more, see http://www.ros.org/wiki/xacro -->
  <!-- body -->
  <!-- trunk -->
  <!-- Floating-base Joint -->
  <joint name="floating_base" type="fixed">
    <origin rpy="0 0 0" xyz="0 0 0"/>
    <parent link="base_link"/>
    <child link="trunk"/>
  </joint>
  <!-- Links -->
  <!-- Footprint link -->
  <link name="base_link">
    <visual>
      <geometry>
        <cylinder length="0.01" radius="0.01"/>
      </geometry>
    </visual>
  </link>
  <!-- Trunk link -->
  <link name="trunk">
    <inertial>
      <origin xyz="-0.02758 -2.3319e-05 0.03103"/>
      <mass value="50.24"/>
      <inertia ixx="0.97322" ixy="-0.0067362" ixz="0.1681" iyy="5.0487" iyz="-0.0060307" izz="5.283"/>
    </inertial>
    <visual>
      <geometry>
        <mesh filename="package://hyq_description/meshes/trunk/trunk.dae" scale="1 1 1"/>
      </geometry>
    </visual>
    <collision>
      <geometry>
        <mesh filename="package://hyq_description/meshes/trunk/trunk.dae" scale="1 1 1"/>
      </geometry>
    </collision>
  </link>
  <!-- Extensions -->
  <gazebo reference="trunk">
    <mu1>0.9</mu1>
    <mu2>0.9</mu2>
  </gazebo>
  <!-- LF leg -->
  <!-- Joints -->
  <!-- Hip assembly joint -->
  <joint name="lf_haa_joint" type="revolute">
    <origin rpy="0 1.57079632679 3.14159265359" xyz="0.3735 0.207 0"/>
    <parent link="trunk"/>
    <child link="lf_hipassembly"/>
    <axis xyz="0 0 1"/>
    <limit effort="150.0" lower="-1.2217304764" upper="0.523598775598" velocity="12.0"/>
    <dynamics damping="0.1" friction="0"/>
    <safety_controller k_position="100" k_velocity="100" soft_lower_limit="-10" soft_upper_limit="12.45"/>
  </joint>
  <!-- Upper leg joint -->
  <joint name="lf_hfe_joint" type="revolute">
    <origin rpy="1.57079632679 0 0" xyz="0.082 0 0"/>
    <parent link="lf_hipassembly"/>
    <child link="lf_upperleg"/>
    <axis xyz="0 0 1"/>
    <limit effort="150.0" lower="-0.872664625997" upper="1.2217304764" velocity="12.0"/>
    <dynamics damping="0.1" friction="0"/>
    <safety_controller k_position="100" k_velocity="100" soft_lower_limit="-10" soft_upper_limit="12.45"/>
  </joint>
  <!-- Lower leg joint -->
  <joint name="lf_kfe_joint" type="revolute">
    <origin rpy="0 0 0" xyz="0.35 0 0"/>
    <parent link="lf_upperleg"/>
    <child link="lf_lowerleg"/>
    <axis xyz="0 0 1"/>
    <limit effort="150.0" lower="-2.44346095279" upper="-0.349065850399" velocity="12.0"/>
    <dynamics damping="0.1" friction="0"/>
    <safety_controller k_position="100" k_velocity="100" soft_lower_limit="-10" soft_upper_limit="12.45"/>
    <!-- Foot joint -->
  </joint>
  <joint name="lf_foot_joint" type="fixed">
    <origin rpy="1.57079632679 0 -1.57079632679" xyz="0.35 0 0"/>
    <parent link="lf_lowerleg"/>
    <child link="lf_foot"/>
  </joint>
  <!-- Links -->
  <!-- Hip assembly link -->
  <link name="lf_hipassembly">
    <inertial>
      <origin xyz="0.04263         0.0         0.16931"/>
      <mass value="2.93"/>
      <inertia ixx="0.134705" ixy="3.6e-05" ixz="0.022734" iyy="0.144171" iyz="5.1e-05" izz="0.011033"/>
    </inertial>
    <visual>
      <origin rpy="0.0 0 0" xyz="0 0 0"/>
      <geometry>
        <mesh filename="package://hyq_description/meshes/leg/hipassembly.dae" scale="1 1 1"/>
      </geometry>
    </visual>
    <collision>
      <origin rpy="0.0 0 0" xyz="0 0 0"/>
      <geometry>
        <mesh filename="package://hyq_description/meshes/leg/hipassembly.dae" scale="1 1 1"/>
      </geometry>
    </collision>
  </link>
  <!-- Upper leg link -->
  <link name="lf_upperleg">
    <inertial>
      <origin xyz="0.15074 0.02625 0.0"/>
      <mass value="2.638"/>
      <inertia ixx="0.005495" ixy="-0.007418" ixz="-0.000102" iyy="0.087136" iyz="-2.1e-05" izz="0.089871"/>
    </inertial>
    <visual>
      <origin rpy="0.0 0 0" xyz="0 0 0"/>
      <geometry>
        <mesh filename="package://hyq_description/meshes/leg/upperleg.dae" scale="1 1 1"/>
      </geometry>
    </visual>
    <collision>
      <origin rpy="0.0 0 0" xyz="0 0 0"/>
      <geometry>
        <mesh filename="package://hyq_description/meshes/leg/upperleg.dae" scale="1 1 1"/>
      </geometry>
    </collision>
  </link>
  <!-- Lower leg link -->
  <link name="lf_lowerleg">
    <inertial>
      <origin xyz="0.1254 5e-05 -0.0001"/>
      <mass value="0.881"/>
      <inertia ixx="0.000468" ixy="0.0" ixz="0.0" iyy="0.026409" iyz="0.0" izz="0.026181"/>
    </inertial>
    <visual>
      <geometry>
        <mesh filename="package://hyq_description/meshes/leg/lowerleg.dae" scale="1 1 1"/>
      </geometry>
    </visual>
    <collision>
      <geometry>
        <mesh filename="package://hyq_description/meshes/leg/lowerleg.dae" scale="1 1 1"/>
      </geometry>
    </collision>
  </link>
  <!-- Foot link -->
  <link name="lf_foot">
    <inertial>
      <origin xyz="0 0 0"/>
      <mass value="0.01"/>
      <inertia ixx="0.0" ixy="0.0" ixz="0.0" iyy="0.0" iyz="0.0" izz="0.0"/>
    </inertial>
    <!--<visual>
				<origin xyz="0.0 0.0 0.0" rpy="0.0 0.0 0.0"/>
				<geometry>
					<sphere radius="0.021"/>
				</geometry>
			</visual>-->
    <collision>
      <origin rpy="0 0 0" xyz="0 0 0"/>
      <geometry>
        <sphere radius="0.02175"/>
      </geometry>
    </collision>
  </link>
  <!-- Extensions -->
  <!-- Hip assembly -->
  <transmission name="lf_haa_trans">
    <type>transmission_interface/SimpleTransmission</type>
    <joint name="lf_haa_joint">
      <hardwareInterface>EffortJointInterface</hardwareInterface>
    </joint>
    <actuator name="lf_haa_motor">
      <hardwareInterface>EffortJointInterface</hardwareInterface>
      <mechanicalReduction>1</mechanicalReduction>
    </actuator>
  </transmission>
  <!-- Upper leg -->
  <transmission name="lf_hfe_upper_trans">
    <type>transmission_interface/SimpleTransmission</type>
    <joint name="lf_hfe_joint">
      <hardwareInterface>EffortJointInterface</hardwareInterface>
    </joint>
    <actuator name="lf_hfe_motor">
      <hardwareInterface>EffortJointInterface</hardwareInterface>
      <mechanicalReduction>1</mechanicalReduction>
    </actuator>
  </transmission>
  <!-- Lower leg -->
  <transmission name="lf_kfe_trans">
    <type>transmission_interface/SimpleTransmission</type>
    <joint name="lf_kfe_joint">
      <hardwareInterface>EffortJointInterface</hardwareInterface>
    </joint>
    <actuator name="lf_kfe_motor">
      <hardwareInterface>EffortJointInterface</hardwareInterface>
      <mechanicalReduction>1</mechanicalReduction>
    </actuator>
  </transmission>
  <gazebo reference="lf_lowerleg">
    <kp>1000000.0</kp>
    <kd>100.0</kd>
    <mu1>1.5</mu1>
    <mu2>1.5</mu2>
    <fdir1>1 0 0</fdir1>
    <maxVel>1.0</maxVel>
    <minDepth>0.00</minDepth>
  </gazebo>
  <!-- RF leg -->
  <!-- Joints -->
  <!-- Hip assembly joint -->
  <joint name="rf_haa_joint" type="revolute">
    <origin rpy="0 1.57079632679 0" xyz="0.3735 -0.207 0"/>
    <parent link="trunk"/>
    <child link="rf_hipassembly"/>
    <axis xyz="0 0 1"/>
    <limit effort="150.0" lower="-1.2217304764" upper="0.523598775598" velocity="12.0"/>
    <dynamics damping="0.1" friction="0"/>
    <safety_controller k_position="100" k_velocity="100" soft_lower_limit="-10" soft_upper_limit="12.45"/>
  </joint>
  <!-- Upper leg joint -->
  <joint name="rf_hfe_joint" type="revolute">
    <origin rpy="-1.57079632679 0 0" xyz="0.082 0 0"/>
    <parent link="rf_hipassembly"/>
    <child link="rf_upperleg"/>
    <axis xyz="0 0 1"/>
    <limit effort="150.0" lower="-0.872664625997" upper="1.2217304764" velocity="12.0"/>
    <dynamics damping="0.1" friction="0"/>
    <safety_controller k_position="100" k_velocity="100" soft_lower_limit="-10" soft_upper_limit="12.45"/>
  </joint>
  <!-- Lower leg joint -->
  <joint name="rf_kfe_joint" type="revolute">
    <origin rpy="0 0 0" xyz="0.35 0 0"/>
    <parent link="rf_upperleg"/>
    <child link="rf_lowerleg"/>
    <axis xyz="0 0 1"/>
    <limit effort="150.0" lower="-2.44346095279" upper="-0.349065850399" velocity="12.0"/>
    <dynamics damping="0.1" friction="0"/>
    <safety_controller k_position="100" k_velocity="100" soft_lower_limit="-10" soft_upper_limit="12.45"/>
    <!-- Foot joint -->
  </joint>
  <joint name="rf_foot_joint" type="fixed">
    <origin rpy="1.57079632679 0 -1.57079632679" xyz="0.35 0 0"/>
    <parent link="rf_lowerleg"/>
    <child link="rf_foot"/>
  </joint>
  <!-- Links -->
  <!-- Hip assembly link -->
  <link name="rf_hipassembly">
    <inertial>
      <origin xyz="0.04263         -0.0         -0.16931"/>
      <mass value="2.93"/>
      <inertia ixx="0.134705" ixy="-3.6e-05" ixz="-0.022734" iyy="0.144171" iyz="5.1e-05" izz="0.011033"/>
    </inertial>
    <visual>
      <origin rpy="3.14159265359 0 0" xyz="0 0 0"/>
      <geometry>
        <mesh filename="package://hyq_description/meshes/leg/hipassembly.dae" scale="1 1 1"/>
      </geometry>
    </visual>
    <collision>
      <origin rpy="3.14159265359 0 0" xyz="0 0 0"/>
      <geometry>
        <mesh filename="package://hyq_description/meshes/leg/hipassembly.dae" scale="1 1 1"/>
      </geometry>
    </collision>
  </link>
  <!-- Upper leg link -->
  <link name="rf_upperleg">
    <inertial>
      <origin xyz="0.15074 -0.02625 0.0"/>
      <mass value="2.638"/>
      <inertia ixx="0.005495" ixy="-0.007418" ixz="-0.000102" iyy="0.087136" iyz="-2.1e-05" izz="0.089871"/>
    </inertial>
    <visual>
      <origin rpy="0.0 0 0" xyz="0 0 0"/>
      <geometry>
        <mesh filename="package://hyq_description/meshes/leg/upperleg.dae" scale="1 1 1"/>
      </geometry>
    </visual>
    <collision>
      <origin rpy="0.0 0 0" xyz="0 0 0"/>
      <geometry>
        <mesh filename="package://hyq_description/meshes/leg/upperleg.dae" scale="1 1 1"/>
      </geometry>
    </collision>
  </link>
  <!-- Lower leg link -->
  <link name="rf_lowerleg">
    <inertial>
      <origin xyz="0.1254 5e-05 -0.0001"/>
      <mass value="0.881"/>
      <inertia ixx="0.000468" ixy="0.0" ixz="0.0" iyy="0.026409" iyz="0.0" izz="0.026181"/>
    </inertial>
    <visual>
      <geometry>
        <mesh filename="package://hyq_description/meshes/leg/lowerleg.dae" scale="1 1 1"/>
      </geometry>
    </visual>
    <collision>
      <geometry>
        <mesh filename="package://hyq_description/meshes/leg/lowerleg.dae" scale="1 1 1"/>
      </geometry>
    </collision>
  </link>
  <!-- Foot link -->
  <link name="rf_foot">
    <inertial>
      <origin xyz="0 0 0"/>
      <mass value="0.01"/>
      <inertia ixx="0.0" ixy="0.0" ixz="0.0" iyy="0.0" iyz="0.0" izz="0.0"/>
    </inertial>
    <!--<visual>
				<origin xyz="0.0 0.0 0.0" rpy="0.0 0.0 0.0"/>
				<geometry>
					<sphere radius="0.021"/>
				</geometry>
			</visual>-->
    <collision>
      <origin rpy="0 0 0" xyz="0 0 0"/>
      <geometry>
        <sphere radius="0.02175"/>
      </geometry>
    </collision>
  </link>
  <!-- Extensions -->
  <!-- Hip assembly -->
  <transmission name="rf_haa_trans">
    <type>transmission_interface/SimpleTransmission</type>
    <joint name="rf_haa_joint">
      <hardwareInterface>EffortJointInterface</hardwareInterface>
    </joint>
    <actuator name="rf_haa_motor">
      <hardwareInterface>EffortJointInterface</hardwareInterface>
      <mechanicalReduction>1</mechanicalReduction>
    </actuator>
  </transmission>
  <!-- Upper leg -->
  <transmission name="rf_hfe_upper_trans">
    <type>transmission_interface/SimpleTransmission</type>
    <joint name="rf_hfe_joint">
      <hardwareInterface>EffortJointInterface</hardwareInterface>
    </joint>
    <actuator name="rf_hfe_motor">
      <hardwareInterface>EffortJointInterface</hardwareInterface>
      <mechanicalReduction>1</mechanicalReduction>
    </actuator>
  </transmission>
  <!-- Lower leg -->
  <transmission name="rf_kfe_trans">
    <type>transmission_interface/SimpleTransmission</type>
    <joint name="rf_kfe_joint">
      <hardwareInterface>EffortJointInterface</hardwareInterface>
    </joint>
    <actuator name="rf_kfe_motor">
      <hardwareInterface>EffortJointInterface</hardwareInterface>
      <mechanicalReduction>1</mechanicalReduction>
    </actuator>
  </transmission>
  <gazebo reference="rf_lowerleg">
    <kp>1000000.0</kp>
    <kd>100.0</kd>
    <mu1>1.5</mu1>
    <mu2>1.5</mu2>
    <fdir1>1 0 0</fdir1>
    <maxVel>1.0</maxVel>
    <minDepth>0.00</minDepth>
  </gazebo>
  <!-- LH leg -->
  <!-- Joints -->
  <!-- Hip assembly joint -->
  <joint name="lh_haa_joint" type="revolute">
    <origin rpy="0 1.57079632679 3.14159265359" xyz="-0.3735 0.207 0"/>
    <parent link="trunk"/>
    <child link="lh_hipassembly"/>
    <axis xyz="0 0 1"/>
    <limit effort="150.0" lower="-1.2217304764" upper="0.523598775598" velocity="12.0"/>
    <dynamics damping="0.1" friction="0"/>
    <safety_controller k_position="100" k_velocity="100" soft_lower_limit="-10" soft_upper_limit="12.45"/>
  </joint>
  <!-- Upper leg joint -->
  <joint name="lh_hfe_joint" type="revolute">
    <origin rpy="1.57079632679 0 0" xyz="0.082 0 0"/>
    <parent link="lh_hipassembly"/>
    <child link="lh_upperleg"/>
    <axis xyz="0 0 1"/>
    <limit effort="150.0" lower="-1.2217304764" upper="0.872664625997" velocity="12.0"/>
    <dynamics damping="0.1" friction="0"/>
    <safety_controller k_position="100" k_velocity="100" soft_lower_limit="-10" soft_upper_limit="12.45"/>
  </joint>
  <!-- Lower leg joint -->
  <joint name="lh_kfe_joint" type="revolute">
    <origin rpy="0 0 0" xyz="0.35 0 0"/>
    <parent link="lh_upperleg"/>
    <child link="lh_lowerleg"/>
    <axis xyz="0 0 1"/>
    <limit effort="150.0" lower="0.349065850399" upper="2.44346095279" velocity="12.0"/>
    <dynamics damping="0.1" friction="0"/>
    <safety_controller k_position="100" k_velocity="100" soft_lower_limit="-10" soft_upper_limit="12.45"/>
    <!-- Foot joint -->
  </joint>
  <joint name="lh_foot_joint" type="fixed">
    <origin rpy="1.57079632679 0 -1.57079632679" xyz="0.35 0 0"/>
    <parent link="lh_lowerleg"/>
    <child link="lh_foot"/>
  </joint>
  <!-- Links -->
  <!-- Hip assembly link -->
  <link name="lh_hipassembly">
    <inertial>
      <origin xyz="0.04263         -0.0         -0.16931"/>
      <mass value="2.93"/>
      <inertia ixx="0.134705" ixy="3.6e-05" ixz="0.022734" iyy="0.144171" iyz="5.1e-05" izz="0.011033"/>
    </inertial>
    <visual>
      <origin rpy="3.14159265359 0 0" xyz="0 0 0"/>
      <geometry>
        <mesh filename="package://hyq_description/meshes/leg/hipassembly.dae" scale="1 1 1"/>
      </geometry>
    </visual>
    <collision>
      <origin rpy="3.14159265359 0 0" xyz="0 0 0"/>
      <geometry>
        <mesh filename="package://hyq_description/meshes/leg/hipassembly.dae" scale="1 1 1"/>
      </geometry>
    </collision>
  </link>
  <!-- Upper leg link -->
  <link name="lh_upperleg">
    <inertial>
      <origin xyz="0.15074 0.02625 0.0"/>
      <mass value="2.638"/>
      <inertia ixx="0.005495" ixy="0.007418" ixz="0.000102" iyy="0.087136" iyz="-2.1e-05" izz="0.089871"/>
    </inertial>
    <visual>
      <origin rpy="3.14159265359 0 0" xyz="0 0 0"/>
      <geometry>
        <mesh filename="package://hyq_description/meshes/leg/upperleg.dae" scale="1 1 1"/>
      </geometry>
    </visual>
    <collision>
      <origin rpy="3.14159265359 0 0" xyz="0 0 0"/>
      <geometry>
        <mesh filename="package://hyq_description/meshes/leg/upperleg.dae" scale="1 1 1"/>
      </geometry>
    </collision>
  </link>
  <!-- Lower leg link -->
  <link name="lh_lowerleg">
    <inertial>
      <origin xyz="0.1254 5e-05 -0.0001"/>
      <mass value="0.881"/>
      <inertia ixx="0.000468" ixy="0.0" ixz="0.0" iyy="0.026409" iyz="0.0" izz="0.026181"/>
    </inertial>
    <visual>
      <geometry>
        <mesh filename="package://hyq_description/meshes/leg/lowerleg.dae" scale="1 1 1"/>
      </geometry>
    </visual>
    <collision>
      <geometry>
        <mesh filename="package://hyq_description/meshes/leg/lowerleg.dae" scale="1 1 1"/>
      </geometry>
    </collision>
  </link>
  <!-- Foot link -->
  <link name="lh_foot">
    <inertial>
      <origin xyz="0 0 0"/>
      <mass value="0.01"/>
      <inertia ixx="0.0" ixy="0.0" ixz="0.0" iyy="0.0" iyz="0.0" izz="0.0"/>
    </inertial>
    <!--<visual>
				<origin xyz="0.0 0.0 0.0" rpy="0.0 0.0 0.0"/>
				<geometry>
					<sphere radius="0.021"/>
				</geometry>
			</visual>-->
    <collision>
      <origin rpy="0 0 0" xyz="0 0 0"/>
      <geometry>
        <sphere radius="0.02175"/>
      </geometry>
    </collision>
  </link>
  <!-- Extensions -->
  <!-- Hip assembly -->
  <transmission name="lh_haa_trans">
    <type>transmission_interface/SimpleTransmission</type>
    <joint name="lh_haa_joint">
      <hardwareInterface>EffortJointInterface</hardwareInterface>
    </joint>
    <actuator name="lh_haa_motor">
      <hardwareInterface>EffortJointInterface</hardwareInterface>
      <mechanicalReduction>1</mechanicalReduction>
    </actuator>
  </transmission>
  <!-- Upper leg -->
  <transmission name="lh_hfe_upper_trans">
    <type>transmission_interface/SimpleTransmission</type>
    <joint name="lh_hfe_joint">
      <hardwareInterface>EffortJointInterface</hardwareInterface>
    </joint>
    <actuator name="lh_hfe_motor">
      <hardwareInterface>EffortJointInterface</hardwareInterface>
      <mechanicalReduction>1</mechanicalReduction>
    </actuator>
  </transmission>
  <!-- Lower leg -->
  <transmission name="lh_kfe_trans">
    <type>transmission_interface/SimpleTransmission</type>
    <joint name="lh_kfe_joint">
      <hardwareInterface>EffortJointInterface</hardwareInterface>
    </joint>
    <actuator name="lh_kfe_motor">
      <hardwareInterface>EffortJointInterface</hardwareInterface>
      <mechanicalReduction>1</mechanicalReduction>
    </actuator>
  </transmission>
  <gazebo reference="lh_lowerleg">
    <kp>1000000.0</kp>
    <kd>100.0</kd>
    <mu1>1.5</mu1>
    <mu2>1.5</mu2>
    <fdir1>1 0 0</fdir1>
    <maxVel>1.0</maxVel>
    <minDepth>0.00</minDepth>
  </gazebo>
  <!-- RH leg -->
  <!-- Joints -->
  <!-- Hip assembly joint -->
  <joint name="rh_haa_joint" type="revolute">
    <origin rpy="0 1.57079632679 0" xyz="-0.3735 -0.207 0"/>
    <parent link="trunk"/>
    <child link="rh_hipassembly"/>
    <axis xyz="0 0 1"/>
    <limit effort="150.0" lower="-1.2217304764" upper="0.523598775598" velocity="12.0"/>
    <dynamics damping="0.1" friction="0"/>
    <safety_controller k_position="100" k_velocity="100" soft_lower_limit="-10" soft_upper_limit="12.45"/>
  </joint>
  <!-- Upper leg joint -->
  <joint name="rh_hfe_joint" type="revolute">
    <origin rpy="-1.57079632679 0 0" xyz="0.082 0 0"/>
    <parent link="rh_hipassembly"/>
    <child link="rh_upperleg"/>
    <axis xyz="0 0 1"/>
    <limit effort="150.0" lower="-1.2217304764" upper="0.872664625997" velocity="12.0"/>
    <dynamics damping="0.1" friction="0"/>
    <safety_controller k_position="100" k_velocity="100" soft_lower_limit="-10" soft_upper_limit="12.45"/>
  </joint>
  <!-- Lower leg joint -->
  <joint name="rh_kfe_joint" type="revolute">
    <origin rpy="0 0 0" xyz="0.35 0 0"/>
    <parent link="rh_upperleg"/>
    <child link="rh_lowerleg"/>
    <axis xyz="0 0 1"/>
    <limit effort="150.0" lower="0.349065850399" upper="2.44346095279" velocity="12.0"/>
    <dynamics damping="0.1" friction="0"/>
    <safety_controller k_position="100" k_velocity="100" soft_lower_limit="-10" soft_upper_limit="12.45"/>
    <!-- Foot joint -->
  </joint>
  <joint name="rh_foot_joint" type="fixed">
    <origin rpy="1.57079632679 0 -1.57079632679" xyz="0.35 0 0"/>
    <parent link="rh_lowerleg"/>
    <child link="rh_foot"/>
  </joint>
  <!-- Links -->
  <!-- Hip assembly link -->
  <link name="rh_hipassembly">
    <inertial>
      <origin xyz="0.04263         0.0         0.16931"/>
      <mass value="2.93"/>
      <inertia ixx="0.134705" ixy="-3.6e-05" ixz="-0.022734" iyy="0.144171" iyz="5.1e-05" izz="0.011033"/>
    </inertial>
    <visual>
      <origin rpy="0.0 0 0" xyz="0 0 0"/>
      <geometry>
        <mesh filename="package://hyq_description/meshes/leg/hipassembly.dae" scale="1 1 1"/>
      </geometry>
    </visual>
    <collision>
      <origin rpy="0.0 0 0" xyz="0 0 0"/>
      <geometry>
        <mesh filename="package://hyq_description/meshes/leg/hipassembly.dae" scale="1 1 1"/>
      </geometry>
    </collision>
  </link>
  <!-- Upper leg link -->
  <link name="rh_upperleg">
    <inertial>
      <origin xyz="0.15074 -0.02625 0.0"/>
      <mass value="2.638"/>
      <inertia ixx="0.005495" ixy="0.007418" ixz="0.000102" iyy="0.087136" iyz="-2.1e-05" izz="0.089871"/>
    </inertial>
    <visual>
      <origin rpy="3.14159265359 0 0" xyz="0 0 0"/>
      <geometry>
        <mesh filename="package://hyq_description/meshes/leg/upperleg.dae" scale="1 1 1"/>
      </geometry>
    </visual>
    <collision>
      <origin rpy="3.14159265359 0 0" xyz="0 0 0"/>
      <geometry>
        <mesh filename="package://hyq_description/meshes/leg/upperleg.dae" scale="1 1 1"/>
      </geometry>
    </collision>
  </link>
  <!-- Lower leg link -->
  <link name="rh_lowerleg">
    <inertial>
      <origin xyz="0.1254 5e-05 -0.0001"/>
      <mass value="0.881"/>
      <inertia ixx="0.000468" ixy="0.0" ixz="0.0" iyy="0.026409" iyz="0.0" izz="0.026181"/>
    </inertial>
    <visual>
      <geometry>
        <mesh filename="package://hyq_description/meshes/leg/lowerleg.dae" scale="1 1 1"/>
      </geometry>
    </visual>
    <collision>
      <geometry>
        <mesh filename="package://hyq_description/meshes/leg/lowerleg.dae" scale="1 1 1"/>
      </geometry>
    </collision>
  </link>
  <!-- Foot link -->
  <link name="rh_foot">
    <inertial>
      <origin xyz="0 0 0"/>
      <mass value="0.01"/>
      <inertia ixx="0.0" ixy="0.0" ixz="0.0" iyy="0.0" iyz="0.0" izz="0.0"/>
    </inertial>
    <!--<visual>
				<origin xyz="0.0 0.0 0.0" rpy="0.0 0.0 0.0"/>
				<geometry>
					<sphere radius="0.021"/>
				</geometry>
			</visual>-->
    <collision>
      <origin rpy="0 0 0" xyz="0 0 0"/>
      <geometry>
        <sphere radius="0.02175"/>
      </geometry>
    </collision>
  </link>
  <!-- Extensions -->
  <!-- Hip assembly -->
  <transmission name="rh_haa_trans">
    <type>transmission_interface/SimpleTransmission</type>
    <joint name="rh_haa_joint">
      <hardwareInterface>EffortJointInterface</hardwareInterface>
    </joint>
    <actuator name="rh_haa_motor">
      <hardwareInterface>EffortJointInterface</hardwareInterface>
      <mechanicalReduction>1</mechanicalReduction>
    </actuator>
  </transmission>
  <!-- Upper leg -->
  <transmission name="rh_hfe_upper_trans">
    <type>transmission_interface/SimpleTransmission</type>
    <joint name="rh_hfe_joint">
      <hardwareInterface>EffortJointInterface</hardwareInterface>
    </joint>
    <actuator name="rh_hfe_motor">
      <hardwareInterface>EffortJointInterface</hardwareInterface>
      <mechanicalReduction>1</mechanicalReduction>
    </actuator>
  </transmission>
  <!-- Lower leg -->
  <transmission name="rh_kfe_trans">
    <type>transmission_interface/SimpleTransmission</type>
    <joint name="rh_kfe_joint">
      <hardwareInterface>EffortJointInterface</hardwareInterface>
    </joint>
    <actuator name="rh_kfe_motor">
      <hardwareInterface>EffortJointInterface</hardwareInterface>
      <mechanicalReduction>1</mechanicalReduction>
    </actuator>
  </transmission>
  <gazebo reference="rh_lowerleg">
    <kp>1000000.0</kp>
    <kd>100.0</kd>
    <mu1>1.5</mu1>
    <mu2>1.5</mu2>
    <fdir1>1 0 0</fdir1>
    <maxVel>1.0</maxVel>
    <minDepth>0.00</minDepth>
  </gazebo>
  <!-- IMU trunk -->
  <!-- Joint -->
  <joint name="3dmgx325_trunk_imu_joint" type="fixed">
    <origin rpy="0 -3.14159265359 0" xyz="0.3 0 0.095"/>
    <parent link="trunk"/>
    <child link="3dmgx325_trunk_imu"/>
  </joint>
  <!-- Link -->
  <link name="3dmgx325_trunk_imu">
    <inertial>
      <origin xyz="-0.00020  0.00010  0.00110"/>
      <mass value="0.018"/>
      <inertia ixx="0.0" ixy="0.0" ixz="0.0" iyy="0.0" iyz="0.0" izz="0.0"/>
    </inertial>
    <visual>
      <origin rpy="0 0 0" xyz="0 0 0"/>
      <geometry>
        <box size="0.02 0.02 0.02"/>
      </geometry>
    </visual>
  </link>
  <!-- IMU definition -->
  <gazebo>
    <plugin filename="libgazebo_ros_imu.so" name="3dmgx325_trunk_imu_controller">
      <alwaysOn>true</alwaysOn>
      <updateRate>100.0</updateRate>
      <bodyName>3dmgx325_trunk_imu</bodyName>
      <topicName>trunk_imu/data</topicName>
      <gaussianNoise>2.89e-08</gaussianNoise>
      <xyzOffset>0 0 0</xyzOffset>
      <rpyOffset>0 0 0</rpyOffset>
      <serviceName>/default_imu</serviceName>
    </plugin>
  </gazebo>
  <!-- Velodyne -->
  <!-- Joints -->
  <joint name="trunk_mount_velodyne_joint" type="fixed">
    <origin rpy="0 0 0" xyz="0.39 0 0.269"/>
    <parent link="trunk"/>
    <child link="trunk_mount_velodyne_frame"/>
  </joint>
  <!-- velodyne sensor optical frame -->
  <joint name="trunk_mount_velodyne_optical_frame_joint" type="fixed">
    <origin rpy="0.0 0.0 0.0" xyz="0.0 0.0 0.09"/>
    <parent link="trunk_mount_velodyne_frame"/>
    <child link="trunk_mount_velodyne_optical_frame"/>
  </joint>
  <!-- Links -->
  <link name="trunk_mount_velodyne_frame">
    <inertial>
      <mass value="0.1"/>
      <origin rpy="0.0 0.0 0.0" xyz="0.0 0.0 0.0"/>
      <inertia ixx="0.01" ixy="0.0" ixz="0.0" iyy="0.01" iyz="0.0" izz="0.01"/>
    </inertial>
    <visual>
      <origin rpy="0 0 0" xyz="0 0 0"/>
      <geometry>
        <mesh filename="package://hyq_description/meshes/sensors/velodyne_hdl32e.dae" scale="1 1 1"/>
      </geometry>
      <material name="gray">
        <color rgba="0.5 0.5 0.5 1"/>
      </material>
    </visual>
    <collision>
      <origin rpy="0 0 0" xyz="0 0 0"/>
      <geometry>
        <box size="0.1 0.18 0.1"/>
      </geometry>
    </collision>
  </link>
  <!-- rgb optical sensor link -->
  <link name="trunk_mount_velodyne_optical_frame">
    <inertial>
      <mass value="0.1"/>
      <origin rpy="0 0 0" xyz="0 0 0"/>
      <inertia ixx="0.01" ixy="0.0" ixz="0.0" iyy="0.01" iyz="0.0" izz="0.01"/>
    </inertial>
  </link>
  <!-- gazebo extensions -->
  <gazebo reference="trunk_mount_velodyne_optical_frame">
    <sensor name="trunk_mount_velodyne_optical_frame_velodyne_sensor" type="ray">
      <always_on>true</always_on>
      <update_rate>1.0</update_rate>
      <pose>0 0 0 0 0 0</pose>
      <ray>
        <scan>
          <horizontal>
            <samples>300</samples>
            <resolution>1</resolution>
            <min_angle>-3.14159265359</min_angle>
            <max_angle>3.14159265359</max_angle>
          </horizontal>
          <vertical>
            <samples>32</samples>
            <resolution>1</resolution>
            <min_angle>-0.535292481587</min_angle>
            <max_angle>0.186226631188</max_angle>
          </vertical>
        </scan>
        <range>
          <min>1.0</min>
          <max>20.0</max>
          <resolution>0.02</resolution>
        </range>
      </ray>
      <!-- test plugin -->
      <plugin filename="libgazebo_ros_block_laser.so" name="trunk_mount_velodyne_optical_frame_controller">
        <gaussianNoise>0.005</gaussianNoise>
        <alwaysOn>true</alwaysOn>
        <updateRate>10</updateRate>
        <topicName>/trunk_mount_velodyne/velodyne_pointcloud</topicName>
        <frameName>trunk_mount_velodyne_frame</frameName>
        <hokuyoMinIntensity>101</hokuyoMinIntensity>
      </plugin>
    </sensor>
  </gazebo>
  <!-- PTU unit -->
  <!-- Joints -->
  <joint name="ptu_joint" type="fixed">
    <origin rpy="-0.013127 0.569257 -0.007748" xyz="0.657353 0.015447 0.119533"/>
    <parent link="trunk"/>
    <child link="ptu_base_link"/>
  </joint>
  <!-- There's an offset between the origin of the pan joint and the origin of 
        	 the overall device, which is between the mounting screws on its base. -->
  <joint name="ptu_base" type="fixed">
    <origin rpy="0 0 0" xyz="0 -0.011 0.022"/>
    <parent link="ptu_base_link"/>
    <child link="ptu_pan_link"/>
  </joint>
  <!-- The pan joint -->
  <joint name="ptu_pan" type="revolute">
    <origin rpy="-1.57079632679 0 0" xyz="0 0 0.066"/>
    <parent link="ptu_pan_link"/>
    <child link="ptu_tilt_link"/>
    <axis xyz="0 -1 0"/>
    <limit effort="30" lower="-2.775" upper="2.775" velocity="1.0"/>
  </joint>
  <!-- The tilt joint -->
  <joint name="ptu_tilt" type="revolute">
    <origin rpy="-1.57079632679 0 0" xyz="0 0 0"/>
    <parent link="ptu_tilt_link"/>
    <child link="ptu_tilted_link"/>
    <axis xyz="0 1 0"/>
    <limit effort="30" lower="-0.82" upper="0.52" velocity="1.0"/>
  </joint>
  <!-- Fixed joint to provide a convenient attachment point for accessories. -->
  <joint name="ptu_mount" type="fixed">
    <origin rpy="3.14159265359 0 0" xyz="0 0 -0.03912"/>
    <parent link="ptu_tilted_link"/>
    <child link="ptu_mount_link"/>
  </joint>
  <!-- Links -->
  <link name="ptu_pan_link">
    <inertial>
      <origin xyz="0.0 0.0 0.0"/>
      <mass value="0.65"/>
      <inertia ixx="0.01" ixy="0.0" ixz="0.0" iyy="0.01" iyz="0.0" izz="0.01"/>
    </inertial>
    <visual>
      <material name="ptu_body_color">
        <color rgba="0.28 0.28 0.28 1"/>
      </material>
      <geometry>
        <box size="0.045 0.065 0.044"/>
      </geometry>
      <origin xyz="0 0.011 0"/>
    </visual>
    <visual>
      <geometry>
        <box size="0.046 0.044 0.044"/>
      </geometry>
      <origin xyz="-0.045 0.0215 0"/>
    </visual>
    <visual>
      <geometry>
        <cylinder length="0.015" radius="0.005"/>
      </geometry>
      <origin rpy="0 1.57 0" xyz="-0.074 0.021 0"/>
    </visual>
    <collision>
      <geometry>
        <box size="0.045 0.065 0.044"/>
      </geometry>
      <origin xyz="0 0.011 0"/>
    </collision>
    <collision>
      <geometry>
        <box size="0.046 0.044 0.044"/>
      </geometry>
      <origin xyz="-0.045 0.0215 0"/>
    </collision>
    <collision>
      <geometry>
        <cylinder length="0.015" radius="0.005"/>
      </geometry>
      <origin rpy="0 1.57 0" xyz="-0.074 0.021 0"/>
    </collision>
  </link>
  <gazebo reference="ptu_pan_link">
    <material>Gazebo/Grey</material>
  </gazebo>
  <link name="ptu_tilt_link">
    <inertial>
      <origin xyz="0.0 0.0 0.0"/>
      <mass value="0.65"/>
      <inertia ixx="0.01" ixy="0.0" ixz="0.0" iyy="0.01" iyz="0.0" izz="0.01"/>
    </inertial>
    <visual>
      <material name="ptu_body_color">
        <color rgba="0.28 0.28 0.28 1"/>
      </material>
      <geometry>
        <box size="0.045 0.065 0.044"/>
      </geometry>
      <origin xyz="0 0.011 0"/>
    </visual>
    <visual>
      <geometry>
        <box size="0.046 0.044 0.044"/>
      </geometry>
      <origin xyz="-0.045 0.0215 0"/>
    </visual>
    <visual>
      <geometry>
        <cylinder length="0.015" radius="0.005"/>
      </geometry>
      <origin rpy="0 1.57 0" xyz="-0.074 0.021 0"/>
    </visual>
    <collision>
      <geometry>
        <box size="0.045 0.065 0.044"/>
      </geometry>
      <origin xyz="0 0.011 0"/>
    </collision>
    <collision>
      <geometry>
        <box size="0.046 0.044 0.044"/>
      </geometry>
      <origin xyz="-0.045 0.0215 0"/>
    </collision>
    <collision>
      <geometry>
        <cylinder length="0.015" radius="0.005"/>
      </geometry>
      <origin rpy="0 1.57 0" xyz="-0.074 0.021 0"/>
    </collision>
  </link>
  <gazebo reference="ptu_tilt_link">
    <material>Gazebo/Grey</material>
  </gazebo>
  <link name="ptu_base_link">
    <inertial>
      <origin xyz="0.0 0.0 0.0"/>
      <mass value="0.01"/>
      <inertia ixx="0.01" ixy="0.0" ixz="0.0" iyy="0.01" iyz="0.0" izz="0.01"/>
    </inertial>
    <visual>
      <geometry>
        <box size="0.001 0.001 0.001"/>
      </geometry>
      <origin xyz="0 0 0"/>
    </visual>
    <collision>
      <geometry>
        <box size="0.001 0.001 0.001"/>
      </geometry>
      <origin xyz="0 0 0"/>
    </collision>
  </link>
  <link name="ptu_tilted_link">
    <inertial>
      <origin xyz="0.0 0.0 0.0"/>
      <mass value="0.01"/>
      <inertia ixx="0.01" ixy="0.0" ixz="0.0" iyy="0.01" iyz="0.0" izz="0.01"/>
    </inertial>
    <visual>
      <geometry>
        <box size="0.001 0.001 0.001"/>
      </geometry>
      <origin xyz="0 0 0"/>
    </visual>
    <collision>
      <geometry>
        <box size="0.001 0.001 0.001"/>
      </geometry>
      <origin xyz="0 0 0"/>
    </collision>
  </link>
  <link name="ptu_mount_link">
    <inertial>
      <origin xyz="0.0 0.0 0.0"/>
      <mass value="0.01"/>
      <inertia ixx="0.01" ixy="0.0" ixz="0.0" iyy="0.01" iyz="0.0" izz="0.01"/>
    </inertial>
    <visual>
      <geometry>
        <box size="0.001 0.001 0.001"/>
      </geometry>
      <origin xyz="0 0 0"/>
    </visual>
    <collision>
      <geometry>
        <box size="0.001 0.001 0.001"/>
      </geometry>
      <origin xyz="0 0 0"/>
    </collision>
  </link>
  <!-- Extensions -->
  <!-- Pan assembly -->
  <transmission name="ptu_pan_trans">
    <type>transmission_interface/SimpleTransmission</type>
    <joint name="ptu_pan">
      <hardwareInterface>EffortJointInterface</hardwareInterface>
    </joint>
    <actuator name="ptu_pan_motor">
      <hardwareInterface>EffortJointInterface</hardwareInterface>
      <mechanicalReduction>1</mechanicalReduction>
    </actuator>
  </transmission>
  <!-- Tilt assembly -->
  <transmission name="ptu_tilt_trans">
    <type>transmission_interface/SimpleTransmission</type>
    <joint name="ptu_tilt">
      <hardwareInterface>EffortJointInterface</hardwareInterface>
    </joint>
    <actuator name="ptu_tilt_motor">
      <hardwareInterface>EffortJointInterface</hardwareInterface>
      <mechanicalReduction>1</mechanicalReduction>
    </actuator>
  </transmission>
  <!-- Asus Xtion Pro -->
  <!--<origin xyz="0 0.005 0.036" rpy="0 0 0"/> with Bumblebee setup -->
  <!--<origin xyz="0 0 0.04397" rpy="0 0 0"/> with Vislab setup -->
  <!-- Joints -->
  <joint name="head_mount_joint" type="fixed">
    <origin rpy="0 0 0" xyz="0 0.005 0.036"/>
    <parent link="ptu_mount_link"/>
    <child link="head_mount_asus_xtion_mount_link"/>
  </joint>
  <!-- asus ir sensor physical attachment -->
  <joint name="head_mount_asus_xtion_depth_joint" type="fixed">
    <origin rpy="0 0 0" xyz="0.009 0.045 0.035"/>
    <parent link="head_mount_asus_xtion_mount_link"/>
    <child link="head_mount_asus_xtion_depth_frame"/>
  </joint>
  <!-- asus xtion ir sensor frame -->
  <joint name="head_mount_asus_xtion_depth_optical_frame_joint" type="fixed">
    <origin rpy="-1.57079632679 0.0 -1.57079632679" xyz="0 0 0"/>
    <parent link="head_mount_asus_xtion_depth_frame"/>
    <child link="head_mount_asus_xtion_depth_optical_frame"/>
  </joint>
  <!-- asus_xtion rgb sensor physical attachment -->
  <joint name="head_mount_asus_xtion_rgb_joint" type="fixed">
    <origin rpy="0 0 0" xyz="0.009 0.01875 0.035"/>
    <parent link="head_mount_asus_xtion_mount_link"/>
    <child link="head_mount_asus_xtion_rgb_frame"/>
  </joint>
  <!-- asus xtion rgb sensor frame -->
  <joint name="head_mount_asus_xtion_rgb_optical_frame_joint" type="fixed">
    <origin rpy="-1.57079632679 0.0 -1.57079632679" xyz="0 0 0"/>
    <parent link="head_mount_asus_xtion_rgb_frame"/>
    <child link="head_mount_asus_xtion_rgb_optical_frame"/>
  </joint>
  <!-- Links -->
  <link name="head_mount_asus_xtion_mount_link">
    <inertial>
      <mass value="0.1"/>
      <origin rpy="0 0 0" xyz="0 0 0"/>
      <inertia ixx="0.01" ixy="0.0" ixz="0.0" iyy="0.01" iyz="0.0" izz="0.01"/>
    </inertial>
    <visual>
      <origin rpy="0 0 0" xyz="0 0 0"/>
      <geometry>
        <mesh filename="package://hyq_description/meshes/sensors/asus_xtion.dae" scale="1 1 1"/>
      </geometry>
      <material name="gray">
        <color rgba="0.5 0.5 0.5 1"/>
      </material>
    </visual>
    <collision>
      <origin rpy="0 0 0" xyz="0 0 0.035"/>
      <geometry>
        <box size="0.05 .18 0.035"/>
      </geometry>
    </collision>
  </link>
  <!-- ir sensor link -->
  <link name="head_mount_asus_xtion_depth_frame">
    <inertial>
      <mass value="0.1"/>
      <origin rpy="0 0 0" xyz="0 0 0"/>
      <inertia ixx="0.01" ixy="0.0" ixz="0.0" iyy="0.01" iyz="0.0" izz="0.01"/>
    </inertial>
    <visual>
      <origin rpy="0 0 0" xyz="0 0 0"/>
      <geometry>
        <sphere radius="0.0005"/>
      </geometry>
    </visual>
    <collision>
      <origin rpy="0 0 0" xyz="0 0 0"/>
      <geometry>
        <sphere radius="0.0005"/>
      </geometry>
    </collision>
  </link>
  <!-- ir optical sensor link -->
  <link name="head_mount_asus_xtion_depth_optical_frame"/>
  <!-- rgb sensor link -->
  <link name="head_mount_asus_xtion_rgb_frame">
    <inertial>
      <mass value="0.1"/>
      <origin rpy="0 0 0" xyz="0 0 0"/>
      <inertia ixx="0.01" ixy="0.0" ixz="0.0" iyy="0.01" iyz="0.0" izz="0.01"/>
    </inertial>
    <visual>
      <origin rpy="0 0 0" xyz="0 0 0"/>
      <geometry>
        <sphere radius="0.0005"/>
      </geometry>
    </visual>
    <collision>
      <origin rpy="0 0 0" xyz="0 0 0"/>
      <geometry>
        <sphere radius="0.0005"/>
      </geometry>
    </collision>
  </link>
  <!-- rgb optical sensor link -->
  <link name="head_mount_asus_xtion_rgb_optical_frame"/>
  <!-- gazebo extensions -->
  <gazebo reference="head_mount_asus_xtion_depth_frame">
    <sensor name="head_mount_asus_xtion_depth_frame_depth_sensor" type="depth">
      <always_on>true</always_on>
      <update_rate>1.0</update_rate>
      <camera>
        <horizontal_fov>1.01229096616</horizontal_fov>
        <image>
          <format>L8</format>
          <width>640</width>
          <height>480</height>
        </image>
        <clip>
          <near>0.8</near>
          <far>3.5</far>
        </clip>
      </camera>
      <plugin filename="libgazebo_ros_openni_kinect.so" name="head_mount_asus_xtion_depth_frame_controller">
        <baseline>0.2</baseline>
        <alwaysOn>true</alwaysOn>
        <updateRate>1.0</updateRate>
        <cameraName>head_mount_asus_xtion_ir</cameraName>
        <imageTopicName>/head_mount_asus_xtion/depth/image_raw</imageTopicName>
        <cameraInfoTopicName>/head_mount_asus_xtion/depth/camera_info</cameraInfoTopicName>
        <depthImageTopicName>/head_mount_asus_xtion/depth/image_raw</depthImageTopicName>
        <depthImageCameraInfoTopicName>/head_mount_asus_xtion/depth/camera_info</depthImageCameraInfoTopicName>
        <pointCloudTopicName>/head_mount_asus_xtion/depth/points</pointCloudTopicName>
        <frameName>head_mount_asus_xtion_depth_optical_frame</frameName>
        <pointCloudCutoff>0.5</pointCloudCutoff>
        <distortionK1>0.00000001</distortionK1>
        <distortionK2>0.00000001</distortionK2>
        <distortionK3>0.00000001</distortionK3>
        <distortionT1>0.00000001</distortionT1>
        <distortionT2>0.00000001</distortionT2>
        <CxPrime>0</CxPrime>
        <Cx>0</Cx>
        <Cy>0</Cy>
        <focalLength>0</focalLength>
        <hackBaseline>0</hackBaseline>
      </plugin>
    </sensor>
    <material value="Gazebo/Red"/>
  </gazebo>
  <gazebo reference="head_mount_asus_xtion_rgb_frame">
    <sensor name="head_mount_asus_xtion_rgb_frame_rgb_sensor" type="depth">
      <always_on>true</always_on>
      <update_rate>30.0</update_rate>
      <camera>
        <horizontal_fov>1.01229096616</horizontal_fov>
        <image>
          <format>R8G8B8</format>
          <width>640</width>
          <height>480</height>
        </image>
        <clip>
          <near>0.8</near>
          <far>3.5</far>
        </clip>
      </camera>
      <plugin filename="libgazebo_ros_openni_kinect.so" name="head_mount_asus_xtion_rgb_frame_controller">
        <alwaysOn>true</alwaysOn>
        <updateRate>1.0</updateRate>
        <cameraName>head_mount_asus_xtion_rgb</cameraName>
        <imageTopicName>/head_mount_asus_xtion/rgb/image_raw</imageTopicName>
        <cameraInfoTopicName>/head_mount_asus_xtion/rgb/camera_info</cameraInfoTopicName>
        <depthImageTopicName>/head_mount_asus_xtion/depth/image_raw</depthImageTopicName>
        <depthImageCameraInfoTopicName>/head_mount_asus_xtion/depth/camera_info</depthImageCameraInfoTopicName>
        <pointCloudTopicName>/head_mount_asus_xtion/depth_registered/points</pointCloudTopicName>
        <frameName>head_mount_asus_xtion_rgb_optical_frame</frameName>
        <pointCloudCutoff>0.5</pointCloudCutoff>
        <distortionK1>0.00000001</distortionK1>
        <distortionK2>0.00000001</distortionK2>
        <distortionK3>0.00000001</distortionK3>
        <distortionT1>0.00000001</distortionT1>
        <distortionT2>0.00000001</distortionT2>
        <CxPrime>0</CxPrime>
        <Cx>0</Cx>
        <Cy>0</Cy>
        <focalLength>0</focalLength>
        <hackBaseline>0</hackBaseline>
      </plugin>
    </sensor>
    <material value="Gazebo/Red"/>
  </gazebo>
  <!-- Kinect -->
  <!-- is no more used, but we keep it for compatibilty -->
  <!--xacro:kinect_camera
		name="head_mount"
		parent="trunk">
		<origin xyz="0.63 0 0.095" rpy="0 0 0"/>
	</xacro:kinect_camera-->
  <!-- Bumblebee -->
  <joint name="bumblebee_mount_joint" type="fixed">
    <parent link="ptu_mount_link"/>
    <child link="bumblebee_mount_link"/>
    <origin rpy="0 0 0" xyz="0 0 0.018"/>
  </joint>
  <joint name="bumblebee_optical_joint" type="fixed">
    <parent link="bumblebee_mount_link"/>
    <child link="bumblebee_optical_frame"/>
    <!--<origin xyz="0 0 0" rpy="0 0 0"/>-->
    <origin rpy="-1.57079632679 0 -1.57079632679" xyz="0 -0.06 0"/>
  </joint>
  <link name="bumblebee_mount_link">
    <visual>
      <origin rpy="1.57079632679 0 1.57079632679" xyz="0 0 0"/>
      <geometry>
        <mesh filename="package://hyq_description/meshes/sensors/bumblebee.dae"/>
      </geometry>
    </visual>
    <collision>
      <origin rpy="1.57079632679 0 1.57079632679" xyz="0 0 0"/>
      <geometry>
        <mesh filename="package://hyq_description/meshes/sensors/bumblebee.dae"/>
      </geometry>
    </collision>
    <inertial>
      <mass value="0.342"/>
      <inertia ixx="0.00010096866" ixy="0" ixz="0" iyy="0.00076652916" iyz="0" izz="0.0007394325"/>
    </inertial>
  </link>
  <link name="bumblebee_optical_frame">
    <inertial>
      <mass value="1E-6"/>
      <inertia ixx="1E-6" ixy="0" ixz="0" iyy="1E-6" iyz="0" izz="1E-6"/>
    </inertial>
  </link>
  <gazebo reference="bumblebee_mount_link">
    <sensor name="stereo_camera" type="multicamera">
      <update_rate>48</update_rate>
      <camera name="left">
        <pose> 0 0.06 0 0 0 0</pose>
        <horizontal_fov>1.69296937443</horizontal_fov>
        <image>
          <width>640</width>
          <height>480</height>
          <format>R8G8B8</format>
        </image>
        <clip>
          <near>0.05</near>
          <far>300</far>
        </clip>
        <noise>
          <type>gaussian</type>
          <mean>0.0</mean>
          <stddev>0.007</stddev>
        </noise>
      </camera>
      <camera name="right">
        <pose> 0 -0.06 0 0 0 0</pose>
        <horizontal_fov>1.69296937443</horizontal_fov>
        <image>
          <width>640</width>
          <height>480</height>
          <format>R8G8B8</format>
        </image>
        <clip>
          <near>0.05</near>
          <far>300</far>
        </clip>
        <noise>
          <type>gaussian</type>
          <mean>0.0</mean>
          <stddev>0.007</stddev>
        </noise>
      </camera>
      <plugin filename="libgazebo_ros_multicamera.so" name="stereo_camera_controller">
        <alwaysOn>true</alwaysOn>
        <cameraName>bumblebee/camera</cameraName>
        <imageTopicName>image_raw</imageTopicName>
        <cameraInfoTopicName>camera_info</cameraInfoTopicName>
        <frameName>bumblebee_mount_link</frameName>
        <hackBaseline>0.12</hackBaseline>
        <!--<rightFrameName>right_camera_optical_frame</rightFrameName>-->
        <!-- NOTE: Distortion is currently unused -->
        <distortionK1>0.0</distortionK1>
        <distortionK2>0.0</distortionK2>
        <distortionK3>0.0</distortionK3>
        <distortionT1>0.0</distortionT1>
        <distortionT2>0.0</distortionT2>
      </plugin>
    </sensor>
  </gazebo>
  <!--	<xacro:vislab_3dve_72
		name="vislab_3dve"
		parent="ptu_mount_link"
		xyz="0 0 0.025"
		rpy="0 0 0"
		high_res="false"/>-->
</robot>
